Workbook

Sheet 📊 Récap 4 ans
A1: 🌸 L'Univers Créatif d'Anaïs • Récapitulatif 2026 → 2029
A2: INDICATEUR | B2: 2026 (4 mois) | C2: 2027 (12 mois) | D2: 2028 (12 mois) | E2: 2029 (12 mois) | F2: TOTAL 4 ANS | G2: Moy./an
A3: CA brut total (€) | B3: ='📅 2026'!F7 -> 2640 | C3: ='📅 2027'!N7 -> 21888 | D3: ='📅 2028'!N7 -> 26496 | E3: ='📅 2029'!N7 -> 27648 | F3: =SUM(B3:E3) -> 78672 | G3: =F3/3.33 -> 23625.225
A4: Total charges & prélèvements (€) | B4: ='📅 2026'!F17 -> 2324.56 | C4: ='📅 2027'!N17 -> 10372.352 | D4: ='📅 2028'!N17 -> 11627.584 | E4: ='📅 2029'!N17 -> 11891.392 | F4: =SUM(B4:E4) -> 36215.888 | G4: =F4/3.33 -> 10875.642
A5: Résultat net total (€) | B5: ='📅 2026'!F21 -> 315.44 | C5: ='📅 2027'!N21 -> 11515.648 | D5: ='📅 2028'!N21 -> 14868.416 | E5: ='📅 2029'!N21 -> 15756.608 | F5: =SUM(B5:E5) -> 42456.112 | G5: =F5/3.33 -> 12749.583
A6: Nb ateliers total | B6: ='📅 2026'!F5 -> 22 | C6: ='📅 2027'!N5 -> 114 | D6: ='📅 2028'!N5 -> 138 | E6: ='📅 2029'!N5 -> 144 | F6: =SUM(B6:E6) -> 418 | G6: =F6/3.33 -> 125.52553
A7: Taux de marge moyen (%) | B7: ='📅 2026'!F23 -> 0.11948485 | C7: ='📅 2027'!N23 -> 0.52611696 | D7: ='📅 2028'!N23 -> 0.561157 | E7: ='📅 2029'!N23 -> 0.56990046 | F7: =AVERAGE(B7:E7) -> 0.44416482 | G7: =F7 -> 0.44416482
A8: Résultat cumulé fin d'année (€) | B8: ='📅 2026'!F22 -> 315.44 | C8: ='📅 2027'!N22 -> 11515.648 | D8: ='📅 2028'!N22 -> 26384.064 | E8: ='📅 2029'!N22 -> 42140.672 | F8: =E8 -> 42140.672 | G8: =F8/3 -> 14046.891
A9: CFE versée sur la période (€) | B9: ='📅 2026'!F16 -> 0 | C9: ='📅 2027'!N16 -> 200 | D9: ='📅 2028'!N16 -> 400 | E9: ='📅 2029'!N16 -> 400 | F9: =SUM(B9:E9) -> 1000 | G9: =F9/3.33 -> 300.3003
A11: ℹ️ Seuil micro-ent. 2026 : 77 700 €/an • Cotisations sociales : 21,6% du CA • Données saisies dans les onglets annuels (cellules vertes) • Moy./an calculée sur 40 mois d'activité
A12: ℹ️ Taux URSSAF 2026 BIC services : 21,2% du CA • CFE : 0€ en 2026, 50% en 2027, 100% à partir de 2028 • Versement libératoire IR : 1,7% du CA (si option activée dans Hypothèses) • Franchise TVA services : 37 500 €/an • Seuil micro-ent. 2026 : 83 600 €/an

Sheet ⚙️ Hypothèses
A1: 🌸 L'Univers Créatif d'Anaïs
A2: TABLEAU PRÉVISIONNEL 3 ANS • Sept 2026 – Déc 2028
A3: ⚙️ HYPOTHÈSES & PARAMÈTRES
A4: Cellules vertes = saisie manuelle | Cellules blanches = calculées automatiquement
A5: 🧵 Types d'ateliers & Tarifs
A6: Tarif atelier Macramé (adulte, €) | B6: 45 | C6: Prix moyen par participant
A7: Tarif atelier Couture (adulte, €) | B7: 40 | C7: Prix moyen par participant
A8: Tarif atelier Bijoux en résine (adulte, €) | B8: 35 | C8: Prix moyen par participant
A9: Tarif atelier enfant (toutes catégories, €) | B9: 25 | C9: Tarif réduit enfant
A10: Nombre moyen de participants / atelier | B10: 6 | C10: Places disponibles par session
A11: % participants adultes | B11: 0.75
A12: % participants enfants | B12: 0.25
A13: 📅 Capacité & Planning
A14: Nb ateliers / semaine (mercredi + samedi) | B14: 2 | C14: 2 jours selon flyer
A15: Nb semaines d'activité / mois | B15: 4 | C15: En moyenne
A16: Nb semaines de congés / an | B16: 5 | C16: Estimation fermeture
A17: Taux de remplissage moyen (démarrage) | B17: 0.5 | C17: Phase lancement
A18: Taux de remplissage cible (régime normal) | B18: 0.8 | C18: Objectif stabilisé
A19: 📦 Charges mensuelles estimées
A20: Fournitures / consommables (€/mois) | B20: 200 | C20: Matières premières ateliers
A21: Loyer / location salle (€/mois) | B21: 150 | C21: Si location ponctuelle
A22: Abonnements & outils numériques (€/mois) | B22: 30 | C22: Site, réseaux, outils
A23: Frais divers & communication (€/mois) | B23: 50 | C23: Flyers, publicité locale
A24: Cotisations sociales URSSAF micro-ent. (% CA) – BIC services | B24: 0.212 | C24: Taux officiel 2026 BIC prestations de services (ateliers artisanaux)
A25: 📈 Hypothèses de croissance
A26: Croissance mensuelle N1 (sept-déc 2026) | B26: 0.1 | C26: Phase lancement rapide
A27: Croissance mensuelle N2 (2027) | B27: 0.03 | C27: Stabilisation progressive
A28: Croissance mensuelle N3 (2028) | B28: 0.02 | C28: Régime de croisière
A29: Tarif moyen atelier retenu (€) | B29: 40 | C29: Mix adulte/enfant/types
A30: ℹ️ Seuil micro-entreprise services 2026 : 77 700 € / an | Plafond TVA franchise : 36 800 €
A31: 🏛️ FISCALITÉ – TVA, CFE, Versement Libératoire & IR
A32: Seuil franchise TVA services (€/an) | B32: 37500 | C32: En-dessous : pas de TVA à facturer (2026)
A33: Seuil tolérance TVA services (€/an) | B33: 41250 | C33: En dépassant ponctuellement ce seuil → TVA dès le 1er jour
A34: Option versement libératoire IR ? | B34: OUI | C34: OUI = IR inclus dans déclaration URSSAF | NON = prélèvement à la source classique
A35: Taux versement libératoire IR (% CA) | B35: 0.017 | C35: 1,7% pour BIC services (si option activée)
A36: CFE – Cotisation minimale estimée (€/an) | B36: 400 | C36: Montant moyen commune petite ville (variable 250€-800€)
A37: CFE – % applicable en 2026 (année création) | B37: 0 | C37: Exonération totale 1ère année civile d'activité
A38: CFE – % applicable en 2027 (2ème année) | B38: 0.5 | C38: Base réduite de 50% la 2ème année d'activité
A39: CFE – % applicable en 2028 et après | B39: 1 | C39: 100% de la cotisation minimale à partir de la 3ème année
A40: ℹ️ TVA : Anaïs est en franchise de base TVA tant que son CA annuel reste sous 37 500 €. Si le CA dépasse 41 250 € → assujettissement à la TVA à partir du 1er jour du mois de dépassement. Les onglets annuels affichent une alerte automatique.
...

Sheet 📅 2026
A1: 🌸 L'Univers Créatif d'Anaïs • Prévisionnel 2026
A2: Cellules vertes = saisie manuelle | Formules = calcul automatique | Modifier les hypothèses dans l'onglet ⚙️
A3: LIBELLÉ | B3: SEPTEMBRE | C3: OCTOBRE | D3: NOVEMBRE | E3: DÉCEMBRE | F3: TOTAL 2026
A4: 💰 RECETTES
A5: Nb d'ateliers réalisés dans le mois | B5: 4 | C5: 5 | D5: 6 | E5: 7 | F5: =SUM(B5:E5) -> 22
A6: Nb moyen participants / atelier (hyp.) | B6: ='⚙️ Hypothèses'!B10*'⚙️ Hypothèses'!B17 -> 3 | C6: ='⚙️ Hypothèses'!B10*'⚙️ Hypothèses'!B17 -> 3 | D6: ='⚙️ Hypothèses'!B10*'⚙️ Hypothèses'!B17 -> 3 | E6: ='⚙️ Hypothèses'!B10*'⚙️ Hypothèses'!B17 -> 3 | F6: =AVERAGE(B6:E6) -> 3
A7: Chiffre d'Affaires brut (€) | B7: =B5*B6*'⚙️ Hypothèses'!B29 -> 480 | C7: =C5*C6*'⚙️ Hypothèses'!B29 -> 600 | D7: =D5*D6*'⚙️ Hypothèses'!B29 -> 720 | E7: =E5*E6*'⚙️ Hypothèses'!B29 -> 840 | F7: =SUM(B7:E7) -> 2640
A8: 📦 CHARGES
A9: Fournitures & consommables (€) | B9: ='⚙️ Hypothèses'!B20 -> 200 | C9: ='⚙️ Hypothèses'!B20 -> 200 | D9: ='⚙️ Hypothèses'!B20 -> 200 | E9: ='⚙️ Hypothèses'!B20 -> 200 | F9: =SUM(B9:E9) -> 800
A10: Loyer / location salle (€) | B10: ='⚙️ Hypothèses'!B21 -> 150 | C10: ='⚙️ Hypothèses'!B21 -> 150 | D10: ='⚙️ Hypothèses'!B21 -> 150 | E10: ='⚙️ Hypothèses'!B21 -> 150 | F10: =SUM(B10:E10) -> 600
A11: Abonnements & outils numériques (€) | B11: ='⚙️ Hypothèses'!B22 -> 30 | C11: ='⚙️ Hypothèses'!B22 -> 30 | D11: ='⚙️ Hypothèses'!B22 -> 30 | E11: ='⚙️ Hypothèses'!B22 -> 30 | F11: =SUM(B11:E11) -> 120
A12: Frais divers & communication (€) | B12: ='⚙️ Hypothèses'!B23 -> 50 | C12: ='⚙️ Hypothèses'!B23 -> 50 | D12: ='⚙️ Hypothèses'!B23 -> 50 | E12: ='⚙️ Hypothèses'!B23 -> 50 | F12: =SUM(B12:E12) -> 200
A13: Cotisations sociales micro-ent. (€) | B13: =B7*'⚙️ Hypothèses'!B24 -> 101.76 | C13: =C7*'⚙️ Hypothèses'!B24 -> 127.2 | D13: =D7*'⚙️ Hypothèses'!B24 -> 152.64 | E13: =E7*'⚙️ Hypothèses'!B24 -> 178.08 | F13: =SUM(B13:E13) -> 559.68
A14: TOTAL CHARGES (€) | B14: =SUM(B9:B13) -> 531.76 | C14: =SUM(C9:C13) -> 557.2 | D14: =SUM(D9:D13) -> 582.64 | E14: =SUM(E9:E13) -> 608.08 | F14: =SUM(B14:E14) -> 2279.68
A15: =IF('⚙️ Hypothèses'!B34="OUI","Versement libératoire IR (€)","Impôt sur revenu – prélèvement à la source (info)") -> Versement libératoire IR (€) | B15: =IF('⚙️ Hypothèses'!B34="OUI",B7*'⚙️ Hypothèses'!B35,0) -> 8.16 | C15: =IF('⚙️ Hypothèses'!B34="OUI",C7*'⚙️ Hypothèses'!B35,0) -> 10.2 | D15: =IF('⚙️ Hypothèses'!B34="OUI",D7*'⚙️ Hypothèses'!B35,0) -> 12.24 | E15: =IF('⚙️ Hypothèses'!B34="OUI",E7*'⚙️ Hypothèses'!B35,0) -> 14.28 | F15: =SUM(B15:E15) -> 44.88
A16: CFE – Cotisation Foncière Entreprises (€/mois) | B16: ='⚙️ Hypothèses'!B36*'⚙️ Hypothèses'!B37/4 -> 0 | C16: ='⚙️ Hypothèses'!B36*'⚙️ Hypothèses'!B37/4 -> 0 | D16: ='⚙️ Hypothèses'!B36*'⚙️ Hypothèses'!B37/4 -> 0 | E16: ='⚙️ Hypothèses'!B36*'⚙️ Hypothèses'!B37/4 -> 0 | F16: =SUM(B16:E16) -> 0
A17: TOTAL CHARGES & PRÉLÈVEMENTS (€) | B17: =SUM(B9:B13)+B15+B16 -> 539.92 | C17: =SUM(C9:C13)+C15+C16 -> 567.4 | D17: =SUM(D9:D13)+D15+D16 -> 594.88 | E17: =SUM(E9:E13)+E15+E16 -> 622.36 | F17: =SUM(B17:E17) -> 2324.56
A18: =IF(F7>'⚙️ Hypothèses'!B33,"🚨 CA dépasse 41 250 € – TVA obligatoire dès ce mois ! Facturer la TVA à 20%",IF(F7>'⚙️ Hypothèses'!B32,"⚠️ CA entre 37 500 € et 41 250 € – Zone de tolérance TVA. Surveiller !","✅ Franchise TVA active – CA sous le seuil de " & TEXT('⚙️ Hypothèses'!B32,"# ##0") & " €")) -> ✅ Franchise TVA active – CA sous le seuil de 37 500 €
A20: 📊 RÉSULTATS
A21: Résultat net mensuel (€) | B21: =B7-B17 -> -59.92 | C21: =C7-C17 -> 32.6 | D21: =D7-D17 -> 125.12 | E21: =E7-E17 -> 217.64 | F21: =SUM(B21:E21) -> 315.44
A22: Résultat cumulé (€) | B22: =B21 -> -59.92 | C22: =B22+C21 -> -27.32 | D22: =C22+D21 -> 97.8 | E22: =D22+E21 -> 315.44 | F22: =E22 -> 315.44
A23: Taux de marge nette (%) | B23: =IF(B7=0,"-",B21/B7) -> -0.12483333 | C23: =IF(C7=0,"-",C21/C7) -> 0.054333333 | D23: =IF(D7=0,"-",D21/D7) -> 0.17377778 | E23: =IF(E7=0,"-",E21/E7) -> 0.25909524 | F23: =IF(F7=0,"-",F21/F7) -> 0.11948485
A24: =IF(F7>77700,"⚠️ Dépassement seuil micro-ent. !",IF(F7>36800,"📢 Franchise TVA approchée","✅ Dans les seuils micro-entreprise")) -> ✅ Dans les seuils micro-entreprise

Sheet 📅 2027
A1: 🌸 L'Univers Créatif d'Anaïs • Prévisionnel 2027
A2: Cellules vertes = saisie manuelle | Formules = calcul automatique | Modifier les hypothèses dans l'onglet ⚙️
A3: LIBELLÉ | B3: JANVIER | C3: FÉVRIER | D3: MARS | E3: AVRIL | F3: MAI | G3: JUIN | H3: JUILLET | I3: AOÛT | J3: SEPTEMBRE | K3: OCTOBRE | L3: NOVEMBRE | M3: DÉCEMBRE | N3: TOTAL 2027
A4: 💰 RECETTES
A5: Nb d'ateliers réalisés dans le mois | B5: 8 | C5: 8 | D5: 8 | E5: 9 | F5: 9 | G5: 9 | H5: 10 | I5: 10 | J5: 10 | K5: 11 | L5: 11 | M5: 11 | N5: =SUM(B5:M5) -> 114
A6: Nb moyen participants / atelier (hyp.) | B6: ='⚙️ Hypothèses'!B10*'⚙️ Hypothèses'!B18 -> 4.8 | C6: ='⚙️ Hypothèses'!B10*'⚙️ Hypothèses'!B18 -> 4.8 | D6: ='⚙️ Hypothèses'!B10*'⚙️ Hypothèses'!B18 -> 4.8 | E6: ='⚙️ Hypothèses'!B10*'⚙️ Hypothèses'!B18 -> 4.8 | F6: ='⚙️ Hypothèses'!B10*'⚙️ Hypothèses'!B18 -> 4.8 | G6: ='⚙️ Hypothèses'!B10*'⚙️ Hypothèses'!B18 -> 4.8 | H6: ='⚙️ Hypothèses'!B10*'⚙️ Hypothèses'!B18 -> 4.8 | I6: ='⚙️ Hypothèses'!B10*'⚙️ Hypothèses'!B18 -> 4.8 | J6: ='⚙️ Hypothèses'!B10*'⚙️ Hypothèses'!B18 -> 4.8 | K6: ='⚙️ Hypothèses'!B10*'⚙️ Hypothèses'!B18 -> 4.8 | L6: ='⚙️ Hypothèses'!B10*'⚙️ Hypothèses'!B18 -> 4.8 | M6: ='⚙️ Hypothèses'!B10*'⚙️ Hypothèses'!B18 -> 4.8 | N6: =AVERAGE(B6:M6) -> 4.8
A7: Chiffre d'Affaires brut (€) | B7: =B5*B6*'⚙️ Hypothèses'!B29 -> 1536 | C7: =C5*C6*'⚙️ Hypothèses'!B29 -> 1536 | D7: =D5*D6*'⚙️ Hypothèses'!B29 -> 1536 | E7: =E5*E6*'⚙️ Hypothèses'!B29 -> 1728 | F7: =F5*F6*'⚙️ Hypothèses'!B29 -> 1728 | G7: =G5*G6*'⚙️ Hypothèses'!B29 -> 1728 | H7: =H5*H6*'⚙️ Hypothèses'!B29 -> 1920 | I7: =I5*I6*'⚙️ Hypothèses'!B29 -> 1920 | J7: =J5*J6*'⚙️ Hypothèses'!B29 -> 1920 | K7: =K5*K6*'⚙️ Hypothèses'!B29 -> 2112 | L7: =L5*L6*'⚙️ Hypothèses'!B29 -> 2112 | M7: =M5*M6*'⚙️ Hypothèses'!B29 -> 2112 | N7: =SUM(B7:M7) -> 21888
A8: 📦 CHARGES
A9: Fournitures & consommables (€) | B9: ='⚙️ Hypothèses'!B20 -> 200 | C9: ='⚙️ Hypothèses'!B20 -> 200 | D9: ='⚙️ Hypothèses'!B20 -> 200 | E9: ='⚙️ Hypothèses'!B20 -> 200 | F9: ='⚙️ Hypothèses'!B20 -> 200 | G9: ='⚙️ Hypothèses'!B20 -> 200 | H9: ='⚙️ Hypothèses'!B20 -> 200 | I9: ='⚙️ Hypothèses'!B20 -> 200 | J9: ='⚙️ Hypothèses'!B20 -> 200 | K9: ='⚙️ Hypothèses'!B20 -> 200 | L9: ='⚙️ Hypothèses'!B20 -> 200 | M9: ='⚙️ Hypothèses'!B20 -> 200 | N9: =SUM(B9:M9) -> 2400
A10: Loyer / location salle (€) | B10: ='⚙️ Hypothèses'!B21 -> 150 | C10: ='⚙️ Hypothèses'!B21 -> 150 | D10: ='⚙️ Hypothèses'!B21 -> 150 | E10: ='⚙️ Hypothèses'!B21 -> 150 | F10: ='⚙️ Hypothèses'!B21 -> 150 | G10: ='⚙️ Hypothèses'!B21 -> 150 | H10: ='⚙️ Hypothèses'!B21 -> 150 | I10: ='⚙️ Hypothèses'!B21 -> 150 | J10: ='⚙️ Hypothèses'!B21 -> 150 | K10: ='⚙️ Hypothèses'!B21 -> 150 | L10: ='⚙️ Hypothèses'!B21 -> 150 | M10: ='⚙️ Hypothèses'!B21 -> 150 | N10: =SUM(B10:M10) -> 1800
A11: Abonnements & outils numériques (€) | B11: ='⚙️ Hypothèses'!B22 -> 30 | C11: ='⚙️ Hypothèses'!B22 -> 30 | D11: ='⚙️ Hypothèses'!B22 -> 30 | E11: ='⚙️ Hypothèses'!B22 -> 30 | F11: ='⚙️ Hypothèses'!B22 -> 30 | G11: ='⚙️ Hypothèses'!B22 -> 30 | H11: ='⚙️ Hypothèses'!B22 -> 30 | I11: ='⚙️ Hypothèses'!B22 -> 30 | J11: ='⚙️ Hypothèses'!B22 -> 30 | K11: ='⚙️ Hypothèses'!B22 -> 30 | L11: ='⚙️ Hypothèses'!B22 -> 30 | M11: ='⚙️ Hypothèses'!B22 -> 30 | N11: =SUM(B11:M11) -> 360
A12: Frais divers & communication (€) | B12: ='⚙️ Hypothèses'!B23 -> 50 | C12: ='⚙️ Hypothèses'!B23 -> 50 | D12: ='⚙️ Hypothèses'!B23 -> 50 | E12: ='⚙️ Hypothèses'!B23 -> 50 | F12: ='⚙️ Hypothèses'!B23 -> 50 | G12: ='⚙️ Hypothèses'!B23 -> 50 | H12: ='⚙️ Hypothèses'!B23 -> 50 | I12: ='⚙️ Hypothèses'!B23 -> 50 | J12: ='⚙️ Hypothèses'!B23 -> 50 | K12: ='⚙️ Hypothèses'!B23 -> 50 | L12: ='⚙️ Hypothèses'!B23 -> 50 | M12: ='⚙️ Hypothèses'!B23 -> 50 | N12: =SUM(B12:M12) -> 600
A13: Cotisations sociales micro-ent. (€) | B13: =B7*'⚙️ Hypothèses'!B24 -> 325.632 | C13: =C7*'⚙️ Hypothèses'!B24 -> 325.632 | D13: =D7*'⚙️ Hypothèses'!B24 -> 325.632 | E13: =E7*'⚙️ Hypothèses'!B24 -> 366.336 | F13: =F7*'⚙️ Hypothèses'!B24 -> 366.336 | G13: =G7*'⚙️ Hypothèses'!B24 -> 366.336 | H13: =H7*'⚙️ Hypothèses'!B24 -> 407.04 | I13: =I7*'⚙️ Hypothèses'!B24 -> 407.04 | J13: =J7*'⚙️ Hypothèses'!B24 -> 407.04 | K13: =K7*'⚙️ Hypothèses'!B24 -> 447.744 | L13: =L7*'⚙️ Hypothèses'!B24 -> 447.744 | M13: =M7*'⚙️ Hypothèses'!B24 -> 447.744 | N13: =SUM(B13:M13) -> 4640.256
A14: TOTAL CHARGES (€) | B14: =SUM(B9:B13) -> 755.632 | C14: =SUM(C9:C13) -> 755.632 | D14: =SUM(D9:D13) -> 755.632 | E14: =SUM(E9:E13) -> 796.336 | F14: =SUM(F9:F13) -> 796.336 | G14: =SUM(G9:G13) -> 796.336 | H14: =SUM(H9:H13) -> 837.04 | I14: =SUM(I9:I13) -> 837.04 | ... M14: =SUM(M9:M13) -> 877.744 | N14: =SUM(B14:M14) -> 9800.256
A15: =IF('⚙️ Hypothèses'!B34="OUI","Versement libératoire IR (€)","Impôt sur revenu – prélèvement à la source (info)") -> Versement libératoire IR (€) | B15: =IF('⚙️ Hypothèses'!B34="OUI",B7*'⚙️ Hypothèses'!B35,0) -> 26.112 | C15: =IF('⚙️ Hypothèses'!B34="OUI",C7*'⚙️ Hypothèses'!B35,0) -> 26.112 | D15: =IF('⚙️ Hypothèses'!B34="OUI",D7*'⚙️ Hypothèses'!B35,0) -> 26.112 | E15: =IF('⚙️ Hypothèses'!B34="OUI",E7*'⚙️ Hypothèses'!B35,0) -> 29.376 | F15: =IF('⚙️ Hypothèses'!B34="OUI",F7*'⚙️ Hypothèses'!B35,0) -> 29.376 | G15: =IF('⚙️ Hypothèses'!B34="OUI",G7*'⚙️ Hypothèses'!B35,0) -> 29.376 | H15: =IF('⚙️ Hypothèses'!B34="OUI",H7*'⚙️ Hypothèses'!B35,0) -> 32.64 | I15: =IF('⚙️ Hypothèses'!B34="OUI",I7*'⚙️ Hypothèses'!B35,0) -> 32.64 | J15: =IF('⚙️ Hypothèses'!B34="OUI",J7*'⚙️ Hypothèses'!B35,0) -> 32.64 | K15: =IF('⚙️ Hypothèses'!B34="OUI",K7*'⚙️ Hypothèses'!B35,0) -> 35.904 | L15: =IF('⚙️ Hypothèses'!B34="OUI",L7*'⚙️ Hypothèses'!B35,0) -> 35.904 | M15: =IF('⚙️ Hypothèses'!B34="OUI",M7*'⚙️ Hypothèses'!B35,0) -> 35.904 | N15: =SUM(B15:M15) -> 372.096
A16: CFE – Cotisation Foncière Entreprises (€/mois) | B16: ='⚙️ Hypothèses'!B36*'⚙️ Hypothèses'!B38/12 -> 16.666667 | C16: ='⚙️ Hypothèses'!B36*'⚙️ Hypothèses'!B38/12 -> 16.666667 | D16: ='⚙️ Hypothèses'!B36*'⚙️ Hypothèses'!B38/12 -> 16.666667 | E16: ='⚙️ Hypothèses'!B36*'⚙️ Hypothèses'!B38/12 -> 16.666667 | F16: ='⚙️ Hypothèses'!B36*'⚙️ Hypothèses'!B38/12 -> 16.666667 | G16: ='⚙️ Hypothèses'!B36*'⚙️ Hypothèses'!B38/12 -> 16.666667 | H16: ='⚙️ Hypothèses'!B36*'⚙️ Hypothèses'!B38/12 -> 16.666667 | I16: ='⚙️ Hypothèses'!B36*'⚙️ Hypothèses'!B38/12 -> 16.666667 | J16: ='⚙️ Hypothèses'!B36*'⚙️ Hypothèses'!B38/12 -> 16.666667 | K16: ='⚙️ Hypothèses'!B36*'⚙️ Hypothèses'!B38/12 -> 16.666667 | L16: ='⚙️ Hypothèses'!B36*'⚙️ Hypothèses'!B38/12 -> 16.666667 | M16: ='⚙️ Hypothèses'!B36*'⚙️ Hypothèses'!B38/12 -> 16.666667 | N16: =SUM(B16:M16) -> 200
A17: TOTAL CHARGES & PRÉLÈVEMENTS (€) | B17: =SUM(B9:B13)+B15+B16 -> 798.41067 | C17: =SUM(C9:C13)+C15+C16 -> 798.41067 | D17: =SUM(D9:D13)+D15+D16 -> 798.41067 | E17: =SUM(E9:E13)+E15+E16 -> 842.37867 | F17: =SUM(F9:F13)+F15+F16 -> 842.37867 | G17: =SUM(G9:G13)+G15+G16 -> 842.37867 | H17: =SUM(H9:H13)+H15+H16 -> 886.34667 | I17: =SUM(I9:I13)+I15+I16 -> 886.34667 | ... M17: =SUM(M9:M13)+M15+M16 -> 930.31467 | N17: =SUM(B17:M17) -> 10372.352
A18: =IF(N7>'⚙️ Hypothèses'!B33,"🚨 CA dépasse 41 250 € – TVA obligatoire dès ce mois ! Facturer la TVA à 20%",IF(N7>'⚙️ Hypothèses'!B32,"⚠️ CA entre 37 500 € et 41 250 € – Zone de tolérance TVA. Surveiller !","✅ Franchise TVA active – CA sous le seuil de " & TEXT('⚙️ Hypothèses'!B32,"# ##0") & " €")) -> ✅ Franchise TVA active – CA sous le seuil de 37 500 €
A20: 📊 RÉSULTATS
A21: Résultat net mensuel (€) | B21: =B7-B17 -> 737.58933 | C21: =C7-C17 -> 737.58933 | D21: =D7-D17 -> 737.58933 | E21: =E7-E17 -> 885.62133 | F21: =F7-F17 -> 885.62133 | G21: =G7-G17 -> 885.62133 | H21: =H7-H17 -> 1033.6533 | I21: =I7-I17 -> 1033.6533 | ... M21: =M7-M17 -> 1181.6853 | N21: =SUM(B21:M21) -> 11515.648
A22: Résultat cumulé depuis sept 2026 (€) | B22: ='📅 2026'!N22+B21 -> 737.58933 | C22: =B22+C21 -> 1475.1787 | D22: =C22+D21 -> 2212.768 | E22: =D22+E21 -> 3098.3893 | F22: =E22+F21 -> 3984.0107 | G22: =F22+G21 -> 4869.632 | H22: =G22+H21 -> 5903.2853 | I22: =H22+I21 -> 6936.9387 | J22: =I22+J21 -> 7970.592 | ... M22: =L22+M21 -> 11515.648 | N22: =M22 -> 11515.648
A23: Taux de marge nette (%) | B23: =IF(B7=0,"-",B21/B7) -> 0.48020139 | C23: =IF(C7=0,"-",C21/C7) -> 0.48020139 | D23: =IF(D7=0,"-",D21/D7) -> 0.48020139 | E23: =IF(E7=0,"-",E21/E7) -> 0.51251235 | F23: =IF(F7=0,"-",F21/F7) -> 0.51251235 | G23: =IF(G7=0,"-",G21/G7) -> 0.51251235 | H23: =IF(H7=0,"-",H21/H7) -> 0.53836111 | I23: =IF(I7=0,"-",I21/I7) -> 0.53836111 | ... N23: =IF(N7=0,"-",N21/N7) -> 0.52611696
A24: =IF(N7>77700,"⚠️ Dépassement seuil micro-ent. !",IF(N7>36800,"📢 Franchise TVA approchée","✅ Dans les seuils micro-entreprise")) -> ✅ Dans les seuils micro-entreprise

Sheet 📅 2028
A1: 🌸 L'Univers Créatif d'Anaïs • Prévisionnel 2028
A2: Cellules vertes = saisie manuelle | Formules = calcul automatique | Modifier les hypothèses dans l'onglet ⚙️
A3: LIBELLÉ | B3: JANVIER | C3: FÉVRIER | D3: MARS | E3: AVRIL | F3: MAI | G3: JUIN | H3: JUILLET | I3: AOÛT | J3: SEPTEMBRE | K3: OCTOBRE | L3: NOVEMBRE | M3: DÉCEMBRE | N3: TOTAL 2028
A4: 💰 RECETTES
A5: Nb d'ateliers réalisés dans le mois | B5: 10 | C5: 10 | D5: 10 | E5: 11 | F5: 11 | G5: 11 | H5: 12 | I5: 12 | J5: 12 | K5: 13 | L5: 13 | M5: 13 | N5: =SUM(B5:M5) -> 138
A6: Nb moyen participants / atelier (hyp.) | B6: ='⚙️ Hypothèses'!B10*'⚙️ Hypothèses'!B18 -> 4.8 | C6: ='⚙️ Hypothèses'!B10*'⚙️ Hypothèses'!B18 -> 4.8 | D6: ='⚙️ Hypothèses'!B10*'⚙️ Hypothèses'!B18 -> 4.8 | E6: ='⚙️ Hypothèses'!B10*'⚙️ Hypothèses'!B18 -> 4.8 | F6: ='⚙️ Hypothèses'!B10*'⚙️ Hypothèses'!B18 -> 4.8 | G6: ='⚙️ Hypothèses'!B10*'⚙️ Hypothèses'!B18 -> 4.8 | H6: ='⚙️ Hypothèses'!B10*'⚙️ Hypothèses'!B18 -> 4.8 | I6: ='⚙️ Hypothèses'!B10*'⚙️ Hypothèses'!B18 -> 4.8 | J6: ='⚙️ Hypothèses'!B10*'⚙️ Hypothèses'!B18 -> 4.8 | K6: ='⚙️ Hypothèses'!B10*'⚙️ Hypothèses'!B18 -> 4.8 | L6: ='⚙️ Hypothèses'!B10*'⚙️ Hypothèses'!B18 -> 4.8 | M6: ='⚙️ Hypothèses'!B10*'⚙️ Hypothèses'!B18 -> 4.8 | N6: =AVERAGE(B6:M6) -> 4.8
A7: Chiffre d'Affaires brut (€) | B7: =B5*B6*'⚙️ Hypothèses'!B29 -> 1920 | C7: =C5*C6*'⚙️ Hypothèses'!B29 -> 1920 | D7: =D5*D6*'⚙️ Hypothèses'!B29 -> 1920 | E7: =E5*E6*'⚙️ Hypothèses'!B29 -> 2112 | F7: =F5*F6*'⚙️ Hypothèses'!B29 -> 2112 | G7: =G5*G6*'⚙️ Hypothèses'!B29 -> 2112 | H7: =H5*H6*'⚙️ Hypothèses'!B29 -> 2304 | I7: =I5*I6*'⚙️ Hypothèses'!B29 -> 2304 | J7: =J5*J6*'⚙️ Hypothèses'!B29 -> 2304 | K7: =K5*K6*'⚙️ Hypothèses'!B29 -> 2496 | L7: =L5*L6*'⚙️ Hypothèses'!B29 -> 2496 | M7: =M5*M6*'⚙️ Hypothèses'!B29 -> 2496 | N7: =SUM(B7:M7) -> 26496
A8: 📦 CHARGES
A9: Fournitures & consommables (€) | B9: ='⚙️ Hypothèses'!B20 -> 200 | C9: ='⚙️ Hypothèses'!B20 -> 200 | D9: ='⚙️ Hypothèses'!B20 -> 200 | E9: ='⚙️ Hypothèses'!B20 -> 200 | F9: ='⚙️ Hypothèses'!B20 -> 200 | G9: ='⚙️ Hypothèses'!B20 -> 200 | H9: ='⚙️ Hypothèses'!B20 -> 200 | I9: ='⚙️ Hypothèses'!B20 -> 200 | J9: ='⚙️ Hypothèses'!B20 -> 200 | K9: ='⚙️ Hypothèses'!B20 -> 200 | L9: ='⚙️ Hypothèses'!B20 -> 200 | M9: ='⚙️ Hypothèses'!B20 -> 200 | N9: =SUM(B9:M9) -> 2400
A10: Loyer / location salle (€) | B10: ='⚙️ Hypothèses'!B21 -> 150 | C10: ='⚙️ Hypothèses'!B21 -> 150 | D10: ='⚙️ Hypothèses'!B21 -> 150 | E10: ='⚙️ Hypothèses'!B21 -> 150 | F10: ='⚙️ Hypothèses'!B21 -> 150 | G10: ='⚙️ Hypothèses'!B21 -> 150 | H10: ='⚙️ Hypothèses'!B21 -> 150 | I10: ='⚙️ Hypothèses'!B21 -> 150 | J10: ='⚙️ Hypothèses'!B21 -> 150 | K10: ='⚙️ Hypothèses'!B21 -> 150 | L10: ='⚙️ Hypothèses'!B21 -> 150 | M10: ='⚙️ Hypothèses'!B21 -> 150 | N10: =SUM(B10:M10) -> 1800
A11: Abonnements & outils numériques (€) | B11: ='⚙️ Hypothèses'!B22 -> 30 | C11: ='⚙️ Hypothèses'!B22 -> 30 | D11: ='⚙️ Hypothèses'!B22 -> 30 | E11: ='⚙️ Hypothèses'!B22 -> 30 | F11: ='⚙️ Hypothèses'!B22 -> 30 | G11: ='⚙️ Hypothèses'!B22 -> 30 | H11: ='⚙️ Hypothèses'!B22 -> 30 | I11: ='⚙️ Hypothèses'!B22 -> 30 | J11: ='⚙️ Hypothèses'!B22 -> 30 | K11: ='⚙️ Hypothèses'!B22 -> 30 | L11: ='⚙️ Hypothèses'!B22 -> 30 | M11: ='⚙️ Hypothèses'!B22 -> 30 | N11: =SUM(B11:M11) -> 360
A12: Frais divers & communication (€) | B12: ='⚙️ Hypothèses'!B23 -> 50 | C12: ='⚙️ Hypothèses'!B23 -> 50 | D12: ='⚙️ Hypothèses'!B23 -> 50 | E12: ='⚙️ Hypothèses'!B23 -> 50 | F12: ='⚙️ Hypothèses'!B23 -> 50 | G12: ='⚙️ Hypothèses'!B23 -> 50 | H12: ='⚙️ Hypothèses'!B23 -> 50 | I12: ='⚙️ Hypothèses'!B23 -> 50 | J12: ='⚙️ Hypothèses'!B23 -> 50 | K12: ='⚙️ Hypothèses'!B23 -> 50 | L12: ='⚙️ Hypothèses'!B23 -> 50 | M12: ='⚙️ Hypothèses'!B23 -> 50 | N12: =SUM(B12:M12) -> 600
A13: Cotisations sociales micro-ent. (€) | B13: =B7*'⚙️ Hypothèses'!B24 -> 407.04 | C13: =C7*'⚙️ Hypothèses'!B24 -> 407.04 | D13: =D7*'⚙️ Hypothèses'!B24 -> 407.04 | E13: =E7*'⚙️ Hypothèses'!B24 -> 447.744 | F13: =F7*'⚙️ Hypothèses'!B24 -> 447.744 | G13: =G7*'⚙️ Hypothèses'!B24 -> 447.744 | H13: =H7*'⚙️ Hypothèses'!B24 -> 488.448 | I13: =I7*'⚙️ Hypothèses'!B24 -> 488.448 | J13: =J7*'⚙️ Hypothèses'!B24 -> 488.448 | K13: =K7*'⚙️ Hypothèses'!B24 -> 529.152 | L13: =L7*'⚙️ Hypothèses'!B24 -> 529.152 | M13: =M7*'⚙️ Hypothèses'!B24 -> 529.152 | N13: =SUM(B13:M13) -> 5617.152
A14: TOTAL CHARGES (€) | B14: =SUM(B9:B13) -> 837.04 | C14: =SUM(C9:C13) -> 837.04 | D14: =SUM(D9:D13) -> 837.04 | E14: =SUM(E9:E13) -> 877.744 | F14: =SUM(F9:F13) -> 877.744 | G14: =SUM(G9:G13) -> 877.744 | H14: =SUM(H9:H13) -> 918.448 | I14: =SUM(I9:I13) -> 918.448 | ... M14: =SUM(M9:M13) -> 959.152 | N14: =SUM(B14:M14) -> 10777.152
A15: =IF('⚙️ Hypothèses'!B34="OUI","Versement libératoire IR (€)","Impôt sur revenu – prélèvement à la source (info)") -> Versement libératoire IR (€) | B15: =IF('⚙️ Hypothèses'!B34="OUI",B7*'⚙️ Hypothèses'!B35,0) -> 32.64 | C15: =IF('⚙️ Hypothèses'!B34="OUI",C7*'⚙️ Hypothèses'!B35,0) -> 32.64 | D15: =IF('⚙️ Hypothèses'!B34="OUI",D7*'⚙️ Hypothèses'!B35,0) -> 32.64 | E15: =IF('⚙️ Hypothèses'!B34="OUI",E7*'⚙️ Hypothèses'!B35,0) -> 35.904 | F15: =IF('⚙️ Hypothèses'!B34="OUI",F7*'⚙️ Hypothèses'!B35,0) -> 35.904 | G15: =IF('⚙️ Hypothèses'!B34="OUI",G7*'⚙️ Hypothèses'!B35,0) -> 35.904 | H15: =IF('⚙️ Hypothèses'!B34="OUI",H7*'⚙️ Hypothèses'!B35,0) -> 39.168 | I15: =IF('⚙️ Hypothèses'!B34="OUI",I7*'⚙️ Hypothèses'!B35,0) -> 39.168 | J15: =IF('⚙️ Hypothèses'!B34="OUI",J7*'⚙️ Hypothèses'!B35,0) -> 39.168 | K15: =IF('⚙️ Hypothèses'!B34="OUI",K7*'⚙️ Hypothèses'!B35,0) -> 42.432 | L15: =IF('⚙️ Hypothèses'!B34="OUI",L7*'⚙️ Hypothèses'!B35,0) -> 42.432 | M15: =IF('⚙️ Hypothèses'!B34="OUI",M7*'⚙️ Hypothèses'!B35,0) -> 42.432 | N15: =SUM(B15:M15) -> 450.432
A16: CFE – Cotisation Foncière Entreprises (€/mois) | B16: ='⚙️ Hypothèses'!B36*'⚙️ Hypothèses'!B39/12 -> 33.333333 | C16: ='⚙️ Hypothèses'!B36*'⚙️ Hypothèses'!B39/12 -> 33.333333 | D16: ='⚙️ Hypothèses'!B36*'⚙️ Hypothèses'!B39/12 -> 33.333333 | E16: ='⚙️ Hypothèses'!B36*'⚙️ Hypothèses'!B39/12 -> 33.333333 | F16: ='⚙️ Hypothèses'!B36*'⚙️ Hypothèses'!B39/12 -> 33.333333 | G16: ='⚙️ Hypothèses'!B36*'⚙️ Hypothèses'!B39/12 -> 33.333333 | H16: ='⚙️ Hypothèses'!B36*'⚙️ Hypothèses'!B39/12 -> 33.333333 | I16: ='⚙️ Hypothèses'!B36*'⚙️ Hypothèses'!B39/12 -> 33.333333 | J16: ='⚙️ Hypothèses'!B36*'⚙️ Hypothèses'!B39/12 -> 33.333333 | K16: ='⚙️ Hypothèses'!B36*'⚙️ Hypothèses'!B39/12 -> 33.333333 | L16: ='⚙️ Hypothèses'!B36*'⚙️ Hypothèses'!B39/12 -> 33.333333 | M16: ='⚙️ Hypothèses'!B36*'⚙️ Hypothèses'!B39/12 -> 33.333333 | N16: =SUM(B16:M16) -> 400
A17: TOTAL CHARGES & PRÉLÈVEMENTS (€) | B17: =SUM(B9:B13)+B15+B16 -> 903.01333 | C17: =SUM(C9:C13)+C15+C16 -> 903.01333 | D17: =SUM(D9:D13)+D15+D16 -> 903.01333 | E17: =SUM(E9:E13)+E15+E16 -> 946.98133 | F17: =SUM(F9:F13)+F15+F16 -> 946.98133 | G17: =SUM(G9:G13)+G15+G16 -> 946.98133 | H17: =SUM(H9:H13)+H15+H16 -> 990.94933 | I17: =SUM(I9:I13)+I15+I16 -> 990.94933 | ... M17: =SUM(M9:M13)+M15+M16 -> 1034.9173 | N17: =SUM(B17:M17) -> 11627.584
A18: =IF(N7>'⚙️ Hypothèses'!B33,"🚨 CA dépasse 41 250 € – TVA obligatoire dès ce mois ! Facturer la TVA à 20%",IF(N7>'⚙️ Hypothèses'!B32,"⚠️ CA entre 37 500 € et 41 250 € – Zone de tolérance TVA. Surveiller !","✅ Franchise TVA active – CA sous le seuil de " & TEXT('⚙️ Hypothèses'!B32,"# ##0") & " €")) -> ✅ Franchise TVA active – CA sous le seuil de 37 500 €
A20: 📊 RÉSULTATS
A21: Résultat net mensuel (€) | B21: =B7-B17 -> 1016.9867 | C21: =C7-C17 -> 1016.9867 | D21: =D7-D17 -> 1016.9867 | E21: =E7-E17 -> 1165.0187 | F21: =F7-F17 -> 1165.0187 | G21: =G7-G17 -> 1165.0187 | H21: =H7-H17 -> 1313.0507 | I21: =I7-I17 -> 1313.0507 | ... M21: =M7-M17 -> 1461.0827 | N21: =SUM(B21:M21) -> 14868.416
A22: Résultat cumulé depuis sept 2026 (€) | B22: ='📅 2027'!N22+B21 -> 12532.635 | C22: =B22+C21 -> 13549.621 | D22: =C22+D21 -> 14566.608 | E22: =D22+E21 -> 15731.627 | F22: =E22+F21 -> 16896.645 | G22: =F22+G21 -> 18061.664 | H22: =G22+H21 -> 19374.715 | I22: =H22+I21 -> 20687.765 | J22: =I22+J21 -> 22000.816 | ... M22: =L22+M21 -> 26384.064 | N22: =M22 -> 26384.064
A23: Taux de marge nette (%) | B23: =IF(B7=0,"-",B21/B7) -> 0.52968056 | C23: =IF(C7=0,"-",C21/C7) -> 0.52968056 | D23: =IF(D7=0,"-",D21/D7) -> 0.52968056 | E23: =IF(E7=0,"-",E21/E7) -> 0.55161869 | F23: =IF(F7=0,"-",F21/F7) -> 0.55161869 | G23: =IF(G7=0,"-",G21/G7) -> 0.55161869 | H23: =IF(H7=0,"-",H21/H7) -> 0.56990046 | I23: =IF(I7=0,"-",I21/I7) -> 0.56990046 | ... N23: =IF(N7=0,"-",N21/N7) -> 0.561157
A24: =IF(N7>77700,"⚠️ Dépassement seuil micro-ent. !",IF(N7>36800,"📢 Franchise TVA approchée","✅ Dans les seuils micro-entreprise")) -> ✅ Dans les seuils micro-entreprise

Sheet 📅 2029
A1: 🌸 L'Univers Créatif d'Anaïs • Prévisionnel 2029
A2: Cellules vertes = saisie manuelle | Formules = calcul automatique | Modifier les hypothèses dans l'onglet ⚙️
A3: LIBELLÉ | B3: JANVIER | C3: FÉVRIER | D3: MARS | E3: AVRIL | F3: MAI | G3: JUIN | H3: JUILLET | I3: AOÛT | J3: SEPTEMBRE | K3: OCTOBRE | L3: NOVEMBRE | M3: DÉCEMBRE | N3: TOTAL 2029
A4: 💰 RECETTES
A5: Nb d'ateliers réalisés dans le mois | B5: 11 | C5: 11 | D5: 11 | E5: 11 | F5: 12 | G5: 12 | H5: 12 | I5: 12 | J5: 13 | K5: 13 | L5: 13 | M5: 13 | N5: =SUM(B5:M5) -> 144
A6: Nb moyen participants / atelier (hyp.) | B6: ='⚙️ Hypothèses'!B10*'⚙️ Hypothèses'!B18 -> 4.8 | C6: ='⚙️ Hypothèses'!B10*'⚙️ Hypothèses'!B18 -> 4.8 | D6: ='⚙️ Hypothèses'!B10*'⚙️ Hypothèses'!B18 -> 4.8 | E6: ='⚙️ Hypothèses'!B10*'⚙️ Hypothèses'!B18 -> 4.8 | F6: ='⚙️ Hypothèses'!B10*'⚙️ Hypothèses'!B18 -> 4.8 | G6: ='⚙️ Hypothèses'!B10*'⚙️ Hypothèses'!B18 -> 4.8 | H6: ='⚙️ Hypothèses'!B10*'⚙️ Hypothèses'!B18 -> 4.8 | I6: ='⚙️ Hypothèses'!B10*'⚙️ Hypothèses'!B18 -> 4.8 | J6: ='⚙️ Hypothèses'!B10*'⚙️ Hypothèses'!B18 -> 4.8 | K6: ='⚙️ Hypothèses'!B10*'⚙️ Hypothèses'!B18 -> 4.8 | L6: ='⚙️ Hypothèses'!B10*'⚙️ Hypothèses'!B18 -> 4.8 | M6: ='⚙️ Hypothèses'!B10*'⚙️ Hypothèses'!B18 -> 4.8 | N6: =AVERAGE(B6:M6) -> 4.8
A7: Chiffre d'Affaires brut (€) | B7: =B5*B6*'⚙️ Hypothèses'!B29 -> 2112 | C7: =C5*C6*'⚙️ Hypothèses'!B29 -> 2112 | D7: =D5*D6*'⚙️ Hypothèses'!B29 -> 2112 | E7: =E5*E6*'⚙️ Hypothèses'!B29 -> 2112 | F7: =F5*F6*'⚙️ Hypothèses'!B29 -> 2304 | G7: =G5*G6*'⚙️ Hypothèses'!B29 -> 2304 | H7: =H5*H6*'⚙️ Hypothèses'!B29 -> 2304 | I7: =I5*I6*'⚙️ Hypothèses'!B29 -> 2304 | J7: =J5*J6*'⚙️ Hypothèses'!B29 -> 2496 | K7: =K5*K6*'⚙️ Hypothèses'!B29 -> 2496 | L7: =L5*L6*'⚙️ Hypothèses'!B29 -> 2496 | M7: =M5*M6*'⚙️ Hypothèses'!B29 -> 2496 | N7: =SUM(B7:M7) -> 27648
A8: 📦 CHARGES
A9: Fournitures & consommables (€) | B9: ='⚙️ Hypothèses'!B20 -> 200 | C9: ='⚙️ Hypothèses'!B20 -> 200 | D9: ='⚙️ Hypothèses'!B20 -> 200 | E9: ='⚙️ Hypothèses'!B20 -> 200 | F9: ='⚙️ Hypothèses'!B20 -> 200 | G9: ='⚙️ Hypothèses'!B20 -> 200 | H9: ='⚙️ Hypothèses'!B20 -> 200 | I9: ='⚙️ Hypothèses'!B20 -> 200 | J9: ='⚙️ Hypothèses'!B20 -> 200 | K9: ='⚙️ Hypothèses'!B20 -> 200 | L9: ='⚙️ Hypothèses'!B20 -> 200 | M9: ='⚙️ Hypothèses'!B20 -> 200 | N9: =SUM(B9:M9) -> 2400
A10: Loyer / location salle (€) | B10: ='⚙️ Hypothèses'!B21 -> 150 | C10: ='⚙️ Hypothèses'!B21 -> 150 | D10: ='⚙️ Hypothèses'!B21 -> 150 | E10: ='⚙️ Hypothèses'!B21 -> 150 | F10: ='⚙️ Hypothèses'!B21 -> 150 | G10: ='⚙️ Hypothèses'!B21 -> 150 | H10: ='⚙️ Hypothèses'!B21 -> 150 | I10: ='⚙️ Hypothèses'!B21 -> 150 | J10: ='⚙️ Hypothèses'!B21 -> 150 | K10: ='⚙️ Hypothèses'!B21 -> 150 | L10: ='⚙️ Hypothèses'!B21 -> 150 | M10: ='⚙️ Hypothèses'!B21 -> 150 | N10: =SUM(B10:M10) -> 1800
A11: Abonnements & outils numériques (€) | B11: ='⚙️ Hypothèses'!B22 -> 30 | C11: ='⚙️ Hypothèses'!B22 -> 30 | D11: ='⚙️ Hypothèses'!B22 -> 30 | E11: ='⚙️ Hypothèses'!B22 -> 30 | F11: ='⚙️ Hypothèses'!B22 -> 30 | G11: ='⚙️ Hypothèses'!B22 -> 30 | H11: ='⚙️ Hypothèses'!B22 -> 30 | I11: ='⚙️ Hypothèses'!B22 -> 30 | J11: ='⚙️ Hypothèses'!B22 -> 30 | K11: ='⚙️ Hypothèses'!B22 -> 30 | L11: ='⚙️ Hypothèses'!B22 -> 30 | M11: ='⚙️ Hypothèses'!B22 -> 30 | N11: =SUM(B11:M11) -> 360
A12: Frais divers & communication (€) | B12: ='⚙️ Hypothèses'!B23 -> 50 | C12: ='⚙️ Hypothèses'!B23 -> 50 | D12: ='⚙️ Hypothèses'!B23 -> 50 | E12: ='⚙️ Hypothèses'!B23 -> 50 | F12: ='⚙️ Hypothèses'!B23 -> 50 | G12: ='⚙️ Hypothèses'!B23 -> 50 | H12: ='⚙️ Hypothèses'!B23 -> 50 | I12: ='⚙️ Hypothèses'!B23 -> 50 | J12: ='⚙️ Hypothèses'!B23 -> 50 | K12: ='⚙️ Hypothèses'!B23 -> 50 | L12: ='⚙️ Hypothèses'!B23 -> 50 | M12: ='⚙️ Hypothèses'!B23 -> 50 | N12: =SUM(B12:M12) -> 600
A13: Cotisations sociales micro-ent. (€) | B13: =B7*'⚙️ Hypothèses'!B24 -> 447.744 | C13: =C7*'⚙️ Hypothèses'!B24 -> 447.744 | D13: =D7*'⚙️ Hypothèses'!B24 -> 447.744 | E13: =E7*'⚙️ Hypothèses'!B24 -> 447.744 | F13: =F7*'⚙️ Hypothèses'!B24 -> 488.448 | G13: =G7*'⚙️ Hypothèses'!B24 -> 488.448 | H13: =H7*'⚙️ Hypothèses'!B24 -> 488.448 | I13: =I7*'⚙️ Hypothèses'!B24 -> 488.448 | J13: =J7*'⚙️ Hypothèses'!B24 -> 529.152 | K13: =K7*'⚙️ Hypothèses'!B24 -> 529.152 | L13: =L7*'⚙️ Hypothèses'!B24 -> 529.152 | M13: =M7*'⚙️ Hypothèses'!B24 -> 529.152 | N13: =SUM(B13:M13) -> 5861.376
A14: TOTAL CHARGES (€) | B14: =SUM(B9:B13) -> 877.744 | C14: =SUM(C9:C13) -> 877.744 | D14: =SUM(D9:D13) -> 877.744 | E14: =SUM(E9:E13) -> 877.744 | F14: =SUM(F9:F13) -> 918.448 | G14: =SUM(G9:G13) -> 918.448 | H14: =SUM(H9:H13) -> 918.448 | I14: =SUM(I9:I13) -> 918.448 | ... M14: =SUM(M9:M13) -> 959.152 | N14: =SUM(B14:M14) -> 11021.376
A15: =IF('⚙️ Hypothèses'!B34="OUI","Versement libératoire IR (€)","Impôt sur revenu – prélèvement à la source (info)") -> Versement libératoire IR (€) | B15: =IF('⚙️ Hypothèses'!B34="OUI",B7*'⚙️ Hypothèses'!B35,0) -> 35.904 | C15: =IF('⚙️ Hypothèses'!B34="OUI",C7*'⚙️ Hypothèses'!B35,0) -> 35.904 | D15: =IF('⚙️ Hypothèses'!B34="OUI",D7*'⚙️ Hypothèses'!B35,0) -> 35.904 | E15: =IF('⚙️ Hypothèses'!B34="OUI",E7*'⚙️ Hypothèses'!B35,0) -> 35.904 | F15: =IF('⚙️ Hypothèses'!B34="OUI",F7*'⚙️ Hypothèses'!B35,0) -> 39.168 | G15: =IF('⚙️ Hypothèses'!B34="OUI",G7*'⚙️ Hypothèses'!B35,0) -> 39.168 | H15: =IF('⚙️ Hypothèses'!B34="OUI",H7*'⚙️ Hypothèses'!B35,0) -> 39.168 | I15: =IF('⚙️ Hypothèses'!B34="OUI",I7*'⚙️ Hypothèses'!B35,0) -> 39.168 | J15: =IF('⚙️ Hypothèses'!B34="OUI",J7*'⚙️ Hypothèses'!B35,0) -> 42.432 | K15: =IF('⚙️ Hypothèses'!B34="OUI",K7*'⚙️ Hypothèses'!B35,0) -> 42.432 | L15: =IF('⚙️ Hypothèses'!B34="OUI",L7*'⚙️ Hypothèses'!B35,0) -> 42.432 | M15: =IF('⚙️ Hypothèses'!B34="OUI",M7*'⚙️ Hypothèses'!B35,0) -> 42.432 | N15: =SUM(B15:M15) -> 470.016
A16: CFE – Cotisation Foncière Entreprises (€/mois) | B16: ='⚙️ Hypothèses'!B36*'⚙️ Hypothèses'!B39/12 -> 33.333333 | C16: ='⚙️ Hypothèses'!B36*'⚙️ Hypothèses'!B39/12 -> 33.333333 | D16: ='⚙️ Hypothèses'!B36*'⚙️ Hypothèses'!B39/12 -> 33.333333 | E16: ='⚙️ Hypothèses'!B36*'⚙️ Hypothèses'!B39/12 -> 33.333333 | F16: ='⚙️ Hypothèses'!B36*'⚙️ Hypothèses'!B39/12 -> 33.333333 | G16: ='⚙️ Hypothèses'!B36*'⚙️ Hypothèses'!B39/12 -> 33.333333 | H16: ='⚙️ Hypothèses'!B36*'⚙️ Hypothèses'!B39/12 -> 33.333333 | I16: ='⚙️ Hypothèses'!B36*'⚙️ Hypothèses'!B39/12 -> 33.333333 | J16: ='⚙️ Hypothèses'!B36*'⚙️ Hypothèses'!B39/12 -> 33.333333 | K16: ='⚙️ Hypothèses'!B36*'⚙️ Hypothèses'!B39/12 -> 33.333333 | L16: ='⚙️ Hypothèses'!B36*'⚙️ Hypothèses'!B39/12 -> 33.333333 | M16: ='⚙️ Hypothèses'!B36*'⚙️ Hypothèses'!B39/12 -> 33.333333 | N16: =SUM(B16:M16) -> 400
A17: TOTAL CHARGES & PRÉLÈVEMENTS (€) | B17: =SUM(B9:B13)+B15+B16 -> 946.98133 | C17: =SUM(C9:C13)+C15+C16 -> 946.98133 | D17: =SUM(D9:D13)+D15+D16 -> 946.98133 | E17: =SUM(E9:E13)+E15+E16 -> 946.98133 | F17: =SUM(F9:F13)+F15+F16 -> 990.94933 | G17: =SUM(G9:G13)+G15+G16 -> 990.94933 | H17: =SUM(H9:H13)+H15+H16 -> 990.94933 | I17: =SUM(I9:I13)+I15+I16 -> 990.94933 | ... M17: =SUM(M9:M13)+M15+M16 -> 1034.9173 | N17: =SUM(B17:M17) -> 11891.392
A18: =IF(N7>'⚙️ Hypothèses'!B33,"🚨 CA dépasse 41 250 € – TVA obligatoire dès ce mois ! Facturer la TVA à 20%",IF(N7>'⚙️ Hypothèses'!B32,"⚠️ CA entre 37 500 € et 41 250 € – Zone de tolérance TVA. Surveiller !","✅ Franchise TVA active – CA sous le seuil de " & TEXT('⚙️ Hypothèses'!B32,"# ##0") & " €")) -> ✅ Franchise TVA active – CA sous le seuil de 37 500 €
A20: 📊 RÉSULTATS
A21: Résultat net mensuel (€) | B21: =B7-B17 -> 1165.0187 | C21: =C7-C17 -> 1165.0187 | D21: =D7-D17 -> 1165.0187 | E21: =E7-E17 -> 1165.0187 | F21: =F7-F17 -> 1313.0507 | G21: =G7-G17 -> 1313.0507 | H21: =H7-H17 -> 1313.0507 | I21: =I7-I17 -> 1313.0507 | ... M21: =M7-M17 -> 1461.0827 | N21: =SUM(B21:M21) -> 15756.608
A22: Résultat cumulé depuis sept 2026 (€) | B22: ='📅 2028'!N22+B21 -> 27549.083 | C22: =B22+C21 -> 28714.101 | D22: =C22+D21 -> 29879.12 | E22: =D22+E21 -> 31044.139 | F22: =E22+F21 -> 32357.189 | G22: =F22+G21 -> 33670.24 | H22: =G22+H21 -> 34983.291 | I22: =H22+I21 -> 36296.341 | J22: =I22+J21 -> 37757.424 | ... M22: =L22+M21 -> 42140.672 | N22: =M22 -> 42140.672
A23: Taux de marge nette (%) | B23: =IF(B7=0,"-",B21/B7) -> 0.55161869 | C23: =IF(C7=0,"-",C21/C7) -> 0.55161869 | D23: =IF(D7=0,"-",D21/D7) -> 0.55161869 | E23: =IF(E7=0,"-",E21/E7) -> 0.55161869 | F23: =IF(F7=0,"-",F21/F7) -> 0.56990046 | G23: =IF(G7=0,"-",G21/G7) -> 0.56990046 | H23: =IF(H7=0,"-",H21/H7) -> 0.56990046 | I23: =IF(I7=0,"-",I21/I7) -> 0.56990046 | ... N23: =IF(N7=0,"-",N21/N7) -> 0.56990046
A24: =IF(N7>77700,"⚠️ Dépassement seuil micro-ent. !",IF(N7>36800,"📢 Franchise TVA approchée","✅ Dans les seuils micro-entreprise")) -> ✅ Dans les seuils micro-entreprise
